Workbook

Sheet README
A1: THE UNLOX ACADEMY - DA/DS TRACK
A2: Excel Minor Project - Sales Operations Analytics
A3: Interview-Grade Data Analytics Assessment · 100 Marks
A5: THE SCENARIO
A6: You have just joined the analytics team at a fast-growing multi-category retailer operating across 6 Indian cities.
A7: The head of sales has handed you 5 raw data files - Orders, Customers, Products, Sales Reps, and Targets - and asked
A8: you to answer a set of business questions before the leadership review tomorrow morning.
A10: The data is REAL-WORLD messy: duplicates, missing references, inconsistent case, invalid records, discontinued SKUs.
A11: Part of the assessment is spotting and handling these issues correctly. A wrong-looking answer isn't always wrong -
A12: sometimes the data itself is telling a story.
A14: RULES OF THE ASSESSMENT
A15: 1. Write your answer in the YELLOW cells on each question sheet. Empty answer cell = 0 marks.
... A22: MARKS DISTRIBUTION
A23: Section | B23: Topic | C23: Questions | D23: Marks
A24: Q1 | B24: Lookup Functions (VLOOKUP, INDEX-MATCH, chained lookups) | C24: 8 | D24: 25
A25: Q2 | B25: Data Cleaning & Quality Diagnostics | C25: 6 | D25: 20
A26: Q3 | B26: Conditional Aggregation (SUMIFS, COUNTIFS, IF logic) | C26: 6 | D26: 25
A27: Q4 | B27: Pivot Tables (2D pivots, % of total, calculated fields) | C27: 5 | D27: 20
A28: Q5 | B28: Advanced (Ranking, Running Totals, Multi-condition) | C28: 5 | D28: 10
B29: TOTAL | C29: 30 | D29: 100
A32: PERFORMANCE TIERS
A33: Marks | B33: Tier | C33: Interview Verdict
A34: 85 - 100 | B34: Excellent | C34: Round 1 clear - Excel not a concern
A35: 70 - 84 | B35: Good | C35: Round 1 clear with minor gaps
A36: 55 - 69 | B36: Borderline | C36: Round 1 uncertain - needs revision
A37: 40 - 54 | B37: Weak | C37: Round 1 likely reject - 2 weeks of practice needed
A38: < 40 | B38: Insufficient | C38: Round 1 reject - foundational gaps
A41: DATA SHEETS OVERVIEW
A42: Sheet | B42: Rows | C42: Key Columns | D42: Joins to
A43: Orders | B43: ~2000 | C43: order_id, order_date, customer_id, product_id, sales_rep_id, quantity, unit_price, discount_pct, final_amount, payment_status, ship_city | D43: All others
A44: Customers | B44: 300 | C44: customer_id (PK), customer_name, age, city, segment, signup_date | D44: Orders via customer_id
A45: Products | B45: 60 | C45: product_id (PK), product_name, category, unit_cost, unit_price, is_active | D45: Orders via product_id
A46: Sales_Reps | B46: 30 | C46: rep_id (PK), rep_name, region, hire_date, team_lead_id | D46: Orders via sales_rep_id, self-join via team_lead_id
A47: Targets | B47: 30 × 12 | C47: rep_id (PK), Jan-24 through Dec-24 monthly target values | D47: Sales_Reps via rep_id

Sheet Orders
A1: order_id | B1: order_date | C1: customer_id | D1: product_id | E1: sales_rep_id | F1: quantity | G1: unit_price | H1: discount_pct | I1: final_amount | J1: payment_status | K1: ship_city | L1: Category | M1: Segment | O1: Region (helper) | P1: Age (helper) | Q1: Month (helper) | R1: Margin (helper)
A2: ORD-00001 | B2: 45549 | C2: CUST-0243 | D2: PROD-014 | E2: R007 | F2: 8 | G2: 3620 | H2: 15.4 | I2: 24500.16 | J2: Completed | K2: Pune | L2: =VLOOKUP(D2,Products!A:F,3,FALSE()) -> Apparel | M2: =VLOOKUP(C2,Customers!A:F,5,FALSE()) -> SMB | N2: =AVERAGEIFS(I:I,L:L,"Electronics",M:M,"Corporate") -> 13981.402 | O2: =IFERROR(VLOOKUP(E2,Sales_Reps!$A:$C,3,FALSE()),"") -> North | P2: =IFERROR(VLOOKUP(C2,Customers!$A:$C,3,FALSE()),"") -> 44 | Q2: =TEXT(B2,"mmm-yy") -> Sep-24 | R2: =IFERROR((VLOOKUP(D2,Products!$A:$E,5,FALSE())-VLOOKUP(D2,Products!$A:$E,4,FALSE()))/VLOOKUP(D2,Products!$A:$E,5,FALSE()),"") -> 0.30690608
A3: ORD-00002 | B3: 45340 | C3: CUST-0202 | D3: PROD-020 | E3: R008 | F3: 2 | G3: 820 | H3: 10.8 | I3: 1462.88 | J3: Pending | K3: Chennai | L3: =VLOOKUP(D3,Products!A:F,3,FALSE()) -> Apparel | M3: =VLOOKUP(C3,Customers!A:F,5,FALSE()) -> Retail | O3: =IFERROR(VLOOKUP(E3,Sales_Reps!$A:$C,3,FALSE()),"") -> North | P3: =IFERROR(VLOOKUP(C3,Customers!$A:$C,3,FALSE()),"") -> 39 | Q3: =TEXT(B3,"mmm-yy") -> Feb-24 | R3: =IFERROR((VLOOKUP(D3,Products!$A:$E,5,FALSE())-VLOOKUP(D3,Products!$A:$E,4,FALSE()))/VLOOKUP(D3,Products!$A:$E,5,FALSE()),"") -> 0.52317073
A4: ORD-00003 | B4: 45371 | C4: CUST-0098 | D4: PROD-053 | E4: R009 | F4: 8 | G4: 470 | H4: 3.3 | I4: 3635.92 | J4: Pending | K4: Delhi | L4: =VLOOKUP(D4,Products!A:F,3,FALSE()) -> Sports | M4: =VLOOKUP(C4,Customers!A:F,5,FALSE()) -> Retail | O4: =IFERROR(VLOOKUP(E4,Sales_Reps!$A:$C,3,FALSE()),"") -> South | P4: =IFERROR(VLOOKUP(C4,Customers!$A:$C,3,FALSE()),"") -> 52 | Q4: =TEXT(B4,"mmm-yy") -> Mar-24 | R4: =IFERROR((VLOOKUP(D4,Products!$A:$E,5,FALSE())-VLOOKUP(D4,Products!$A:$E,4,FALSE()))/VLOOKUP(D4,Products!$A:$E,5,FALSE()),"") -> 0.35744681
A5: ORD-00004 | B5: 45413 | C5: CUST-0071 | D5: PROD-028 | E5: R010 | F5: 1 | G5: 3660 | H5: 15.7 | I5: 3085.38 | J5: Completed | K5: Delhi | L5: =VLOOKUP(D5,Products!A:F,3,FALSE()) -> Grocery | M5: =VLOOKUP(C5,Customers!A:F,5,FALSE()) -> Corporate | O5: =IFERROR(VLOOKUP(E5,Sales_Reps!$A:$C,3,FALSE()),"") -> South | P5: =IFERROR(VLOOKUP(C5,Customers!$A:$C,3,FALSE()),"") -> 46 | Q5: =TEXT(B5,"mmm-yy") -> May-24 | R5: =IFERROR((VLOOKUP(D5,Products!$A:$E,5,FALSE())-VLOOKUP(D5,Products!$A:$E,4,FALSE()))/VLOOKUP(D5,Products!$A:$E,5,FALSE()),"") -> 0.39508197
A6: ORD-00005 | B6: 45611 | C6: CUST-0180 | D6: PROD-012 | E6: R011 | F6: 1 | G6: 3160 | H6: 26 | I6: 2338.4 | J6: Completed | K6: Chennai | L6: =VLOOKUP(D6,Products!A:F,3,FALSE()) -> Apparel | M6: =VLOOKUP(C6,Customers!A:F,5,FALSE()) -> Retail | O6: =IFERROR(VLOOKUP(E6,Sales_Reps!$A:$C,3,FALSE()),"") -> South | P6: =IFERROR(VLOOKUP(C6,Customers!$A:$C,3,FALSE()),"") -> 36 | Q6: =TEXT(B6,"mmm-yy") -> Nov-24 | R6: =IFERROR((VLOOKUP(D6,Products!$A:$E,5,FALSE())-VLOOKUP(D6,Products!$A:$E,4,FALSE()))/VLOOKUP(D6,Products!$A:$E,5,FALSE()),"") -> 0.40316456
A7: ORD-00006 | B7: 45406 | C7: CUST-0275 | D7: PROD-032 | E7: R012 | F7: 4 | G7: 370 | H7: 29 | I7: 1050.8 | J7: Completed | K7: Mumbai | L7: =VLOOKUP(D7,Products!A:F,3,FALSE()) -> Home | M7: =VLOOKUP(C7,Customers!A:F,5,FALSE()) -> Retail | O7: =IFERROR(VLOOKUP(E7,Sales_Reps!$A:$C,3,FALSE()),"") -> South | P7: =IFERROR(VLOOKUP(C7,Customers!$A:$C,3,FALSE()),"") -> 36 | Q7: =TEXT(B7,"mmm-yy") -> Apr-24 | R7: =IFERROR((VLOOKUP(D7,Products!$A:$E,5,FALSE())-VLOOKUP(D7,Products!$A:$E,4,FALSE()))/VLOOKUP(D7,Products!$A:$E,5,FALSE()),"") -> 0.22162162
A8: ORD-00007 | B8: 45455 | C8: CUST-0293 | D8: PROD-057 | E8: R013 | F8: 3 | G8: 960 | H8: 5.8 | I8: 2712.96 | J8: Completed | K8: Bengaluru | L8: =VLOOKUP(D8,Products!A:F,3,FALSE()) -> Sports | M8: =VLOOKUP(C8,Customers!A:F,5,FALSE()) -> Retail | O8: =IFERROR(VLOOKUP(E8,Sales_Reps!$A:$C,3,FALSE()),"") -> South | P8: =IFERROR(VLOOKUP(C8,Customers!$A:$C,3,FALSE()),"") -> 27 | Q8: =TEXT(B8,"mmm-yy") -> Jun-24 | R8: =IFERROR((VLOOKUP(D8,Products!$A:$E,5,FALSE())-VLOOKUP(D8,Products!$A:$E,4,FALSE()))/VLOOKUP(D8,Products!$A:$E,5,FALSE()),"") -> 0.265625
A9: ORD-00008 | B9: 45617 | C9: CUST-0281 | D9: PROD-007 | E9: R014 | F9: 8 | G9: 1430 | H9: 2.4 | I9: 11165.44 | J9: Completed | K9: Bengaluru | L9: =VLOOKUP(D9,Products!A:F,3,FALSE()) -> Electronics | M9: =VLOOKUP(C9,Customers!A:F,5,FALSE()) -> Corporate | O9: =IFERROR(VLOOKUP(E9,Sales_Reps!$A:$C,3,FALSE()),"") -> South | P9: =IFERROR(VLOOKUP(C9,Customers!$A:$C,3,FALSE()),"") -> 57 | Q9: =TEXT(B9,"mmm-yy") -> Nov-24 | R9: =IFERROR((VLOOKUP(D9,Products!$A:$E,5,FALSE())-VLOOKUP(D9,Products!$A:$E,4,FALSE()))/VLOOKUP(D9,Products!$A:$E,5,FALSE()),"") -> 0.3979021
A10: ORD-00009 | B10: 45549 | C10: CUST-0260 | D10: PROD-038 | E10: R015 | F10: 3 | G10: 5490 | H10: 14.2 | I10: 14131.26 | J10: Completed | K10: Bengaluru | L10: =VLOOKUP(D10,Products!A:F,3,FALSE()) -> Home | M10: =VLOOKUP(C10,Customers!A:F,5,FALSE()) -> Retail | O10: =IFERROR(VLOOKUP(E10,Sales_Reps!$A:$C,3,FALSE()),"") -> South | P10: =IFERROR(VLOOKUP(C10,Customers!$A:$C,3,FALSE()),"") -> 42 | Q10: =TEXT(B10,"mmm-yy") -> Sep-24 | R10: =IFERROR((VLOOKUP(D10,Products!$A:$E,5,FALSE())-VLOOKUP(D10,Products!$A:$E,4,FALSE()))/VLOOKUP(D10,Products!$A:$E,5,FALSE()),"") -> 0.53570128
A11: ORD-00010 | B11: 45396 | C11: CUST-0147 | D11: PROD-030 | E11: R016 | F11: 3 | G11: 970 | H11: 1.2 | I11: 2875.08 | J11: Completed | K11: Pune | L11: =VLOOKUP(D11,Products!A:F,3,FALSE()) -> Grocery | M11: =VLOOKUP(C11,Customers!A:F,5,FALSE()) -> Retail | O11: =IFERROR(VLOOKUP(E11,Sales_Reps!$A:$C,3,FALSE()),"") -> South | P11: =IFERROR(VLOOKUP(C11,Customers!$A:$C,3,FALSE()),"") -> 56 | Q11: =TEXT(B11,"mmm-yy") -> Apr-24 | R11: =IFERROR((VLOOKUP(D11,Products!$A:$E,5,FALSE())-VLOOKUP(D11,Products!$A:$E,4,FALSE()))/VLOOKUP(D11,Products!$A:$E,5,FALSE()),"") -> 0.55257732
A12: ORD-00011 | B12: 45560 | C12: CUST-0204 | D12: PROD-024 | E12: R017 | F12: 7 | G12: 2270 | H12: 7.1 | I12: 14761.81 | J12: Pending | K12: Hyderabad | L12: =VLOOKUP(D12,Products!A:F,3,FALSE()) -> Grocery | M12: =VLOOKUP(C12,Customers!A:F,5,FALSE()) -> Retail | O12: =IFERROR(VLOOKUP(E12,Sales_Reps!$A:$C,3,FALSE()),"") -> East | P12: =IFERROR(VLOOKUP(C12,Customers!$A:$C,3,FALSE()),"") -> 60 | Q12: =TEXT(B12,"mmm-yy") -> Sep-24 | R12: =IFERROR((VLOOKUP(D12,Products!$A:$E,5,FALSE())-VLOOKUP(D12,Products!$A:$E,4,FALSE()))/VLOOKUP(D12,Products!$A:$E,5,FALSE()),"") -> 0.47004405
A13: ORD-00012 | B13: 45332 | C13: CUST-0147 | D13: PROD-010 | E13: R018 | F13: 9 | G13: 2640 | H13: 21.7 | I13: 18604.08 | J13: Completed | K13: Pune | L13: =VLOOKUP(D13,Products!A:F,3,FALSE()) -> Electronics | M13: =VLOOKUP(C13,Customers!A:F,5,FALSE()) -> Retail | O13: =IFERROR(VLOOKUP(E13,Sales_Reps!$A:$C,3,FALSE()),"") -> East | P13: =IFERROR(VLOOKUP(C13,Customers!$A:$C,3,FALSE()),"") -> 56 | Q13: =TEXT(B13,"mmm-yy") -> Feb-24 | R13: =IFERROR((VLOOKUP(D13,Products!$A:$E,5,FALSE())-VLOOKUP(D13,Products!$A:$E,4,FALSE()))/VLOOKUP(D13,Products!$A:$E,5,FALSE()),"") -> 0.56477273
A14: ORD-00013 | B14: 45507 | C14: CUST-0280 | D14: PROD-002 | E14: R019 | F14: 3 | G14: 2600 | H14: 4.3 | I14: 7464.6 | J14: Cancelled | K14: Delhi | L14: =VLOOKUP(D14,Products!A:F,3,FALSE()) -> Electronics | M14: =VLOOKUP(C14,Customers!A:F,5,FALSE()) -> SMB | O14: =IFERROR(VLOOKUP(E14,Sales_Reps!$A:$C,3,FALSE()),"") -> East | P14: =IFERROR(VLOOKUP(C14,Customers!$A:$C,3,FALSE()),"") -> 27 | Q14: =TEXT(B14,"mmm-yy") -> Aug-24 | R14: =IFERROR((VLOOKUP(D14,Products!$A:$E,5,FALSE())-VLOOKUP(D14,Products!$A:$E,4,FALSE()))/VLOOKUP(D14,Products!$A:$E,5,FALSE()),"") -> 0.59538462
... A2001: ORD-02000 | B2001: 45325 | C2001: CUST-0238 | D2001: PROD-034 | E2001: R2006 | F2001: 6 | G2001: 5080 | H2001: 28.1 | I2001: 21915.12 | J2001: Completed | K2001: Delhi | L2001: =VLOOKUP(D2001,Products!A:F,3,FALSE()) -> Home | M2001: =VLOOKUP(C2001,Customers!A:F,5,FALSE()) -> Retail | O2001: =IFERROR(VLOOKUP(E2001,Sales_Reps!$A:$C,3,FALSE()),"") | P2001: =IFERROR(VLOOKUP(C2001,Customers!$A:$C,3,FALSE()),"") -> 49 | Q2001: =TEXT(B2001,"mmm-yy") -> Feb-24 | R2001: =IFERROR((VLOOKUP(D2001,Products!$A:$E,5,FALSE())-VLOOKUP(D2001,Products!$A:$E,4,FALSE()))/VLOOKUP(D2001,Products!$A:$E,5,FALSE()),"") -> 0.51594488

Sheet Customers
A1: customer_id | B1: customer_name | C1: age | D1: city | E1: segment | F1: signup_date
A2: CUST-0001 | B2: Amit Agarwal | C2: 36 | D2: Pune | E2: Retail | F2: 44819
A3: CUST-0002 | B3: Vihaan Malhotra | C3: 42 | D3: Pune | E3: Corporate | F3: 44984
A4: CUST-0003 | B4: Navya Malhotra | C4: 33 | D4: Mumbai | E4: Retail | F4: 44059
A5: CUST-0004 | B5: Aaradhya Mehta | C5: 53 | D5: delhi | E5: Retail | F5: 44054
A6: CUST-0005 | B6: Myra Malhotra | C6: 52 | D6: Chennai | E6: Corporate | F6: 45037
A7: CUST-0006 | B7: Shaurya Iyer | C7: 44 | D7: Pune | E7: SMB | F7: 44302
A8: CUST-0007 | B8: Dhruv Joshi | C8: 47 | D8: Bengaluru | E8: Retail | F8: 44498
A9: CUST-0008 | B9: Kavita Malhotra | C9: 39 | D9: Pune | E9: SMB | F9: 45162
A10: CUST-0009 | B10: Neha Malhotra | C10: 61 | D10: Mumbai | E10: Retail | F10: 44343
A11: CUST-0010 | B11: Aaradhya Gupta | C11: 61 | D11: Mumbai | E11: SMB | F11: 44975
A12: CUST-0011 | B12: Diya Menon | C12: 41 | D12: Chennai | E12: Corporate | F12: 44821
A13: CUST-0012 | B13: Prisha Desai | C13: 43 | D13: Pune | E13: Retail | F13: 44718
... A301: CUST-0300 | B301: Rohit Nair | C301: 38 | D301: Mumbai | E301: Retail | F301: 43932

Sheet Products
A1: product_id | B1: product_name | C1: category | D1: unit_cost | E1: unit_price | F1: is_active
A2: PROD-001 | B2: Smartphone Pro | C2: Electronics | D2: 2405 | E2: 5330 | F2: =TRUE() -> TRUE
A3: PROD-002 | B3: Wireless Earbuds | C3: Electronics | D3: 1052 | E3: 2600 | F3: =TRUE() -> TRUE
A4: PROD-003 | B4: Smart Watch | C4: Electronics | D4: 1665 | E4: 3570 | F4: =TRUE() -> TRUE
A5: PROD-004 | B5: Laptop Bag | C5: Electronics | D5: 1559 | E5: 3870 | F5: =TRUE() -> TRUE
A6: PROD-005 | B6: Power Bank | C6: Electronics | D6: 128 | E6: 300 | F6: =TRUE() -> TRUE
A7: PROD-006 | B7: Bluetooth Speaker | C7: Electronics | D7: 2865 | E7: 3970 | F7: =TRUE() -> TRUE
A8: PROD-007 | B8: USB-C Cable | C8: Electronics | D8: 861 | E8: 1430 | F8: =TRUE() -> TRUE
A9: PROD-008 | B9: Wireless Mouse | C9: Electronics | D9: 1259 | E9: 2660 | F9: =FALSE() -> FALSE
A10: PROD-009 | B10: Mechanical Keyboard | C10: Electronics | D10: 517 | E10: 1220 | F10: =TRUE() -> TRUE
A11: PROD-010 | B11: Tablet Stand | C11: Electronics | D11: 1149 | E11: 2640 | F11: =TRUE() -> TRUE
A12: PROD-011 | B12: Cotton T-Shirt | C12: Apparel | D12: 1748 | E12: 3450 | F12: =TRUE() -> TRUE
A13: PROD-012 | B13: Denim Jeans | C13: Apparel | D13: 1886 | E13: 3160 | F13: =TRUE() -> TRUE
A14: PROD-013 | B14: Formal Shirt | C14: Apparel | D14: 2611 | E14: 3640 | F14: =TRUE() -> TRUE
A15: PROD-014 | B15: Winter Jacket | C15: Apparel | D15: 2509 | E15: 3620 | F15: =TRUE() -> TRUE
A16: PROD-015 | B16: Sports Shoes | C16: Apparel | D16: 1962 | E16: 2720 | F16: =TRUE() -> TRUE
A17: PROD-016 | B17: Casual Sneakers | C17: Apparel | D17: 396 | E17: 620 | F17: =TRUE() -> TRUE
A18: PROD-017 | B18: Silk Saree | C18: Apparel | D18: 1075 | E18: 2510 | F18: =FALSE() -> FALSE
A19: PROD-018 | B19: Kurta Set | C19: Apparel | D19: 2629 | E19: 3560 | F19: =TRUE() -> TRUE
A20: PROD-019 | B20: Track Pants | C20: Apparel | D20: 1173 | E20: 2480 | F20: =TRUE() -> TRUE
A21: PROD-020 | B21: Woolen Sweater | C21: Apparel | D21: 391 | E21: 820 | F21: =TRUE() -> TRUE
A22: PROD-021 | B22: Basmati Rice 5kg | C22: Grocery | D22: 1435 | E22: 2760 | F22: =TRUE() -> TRUE
A23: PROD-022 | B23: Wheat Flour 10kg | C23: Grocery | D23: 1412 | E23: 2270 | F23: =TRUE() -> TRUE
A24: PROD-023 | B24: Cooking Oil 5L | C24: Grocery | D24: 1182 | E24: 2380 | F24: =TRUE() -> TRUE
A25: PROD-024 | B25: Turmeric Powder 500g | C25: Grocery | D25: 1203 | E25: 2270 | F25: =TRUE() -> TRUE
A26: PROD-025 | B26: Chili Powder 500g | C26: Grocery | D26: 2911 | E26: 4060 | F26: =TRUE() -> TRUE
A27: PROD-026 | B27: Sugar 5kg | C27: Grocery | D27: 2027 | E27: 4070 | F27: =TRUE() -> TRUE
A28: PROD-027 | B28: Tea Leaves 1kg | C28: Grocery | D28: 2436 | E28: 3780 | F28: =TRUE() -> TRUE
A29: PROD-028 | B29: Coffee Beans 500g | C29: Grocery | D29: 2214 | E29: 3660 | F29: =FALSE() -> FALSE
A30: PROD-029 | B30: Ghee 1L | C30: Grocery | D30: 1010 | E30: 2210 | F30: =TRUE() -> TRUE
A31: PROD-030 | B31: Salt 1kg | C31: Grocery | D31: 434 | E31: 970 | F31: =TRUE() -> TRUE
A32: PROD-031 | B32: Bed Sheet Set | C32: Home | D32: 2135 | E32: 3730 | F32: =TRUE() -> TRUE
A33: PROD-032 | B33: Pillow Cover Pair | C33: Home | D33: 288 | E33: 370 | F33: =TRUE() -> TRUE
A34: PROD-033 | B34: Curtain Set | C34: Home | D34: 1143 | E34: 2030 | F34: =TRUE() -> TRUE
A35: PROD-034 | B35: Kitchen Towel Set | C35: Home | D35: 2459 | E35: 5080 | F35: =TRUE() -> TRUE
A36: PROD-035 | B36: Doormat | C36: Home | D36: 464 | E36: 1090 | F36: =TRUE() -> TRUE
A37: PROD-036 | B37: Wall Clock | C37: Home | D37: 1556 | E37: 3250 | F37: =TRUE() -> TRUE
A38: PROD-037 | B38: Table Lamp | C38: Home | D38: 329 | E38: 660 | F38: =TRUE() -> TRUE
A39: PROD-038 | B39: Storage Box | C39: Home | D39: 2549 | E39: 5490 | F39: =TRUE() -> TRUE
A40: PROD-039 | B40: Photo Frame | C40: Home | D40: 1850 | E40: 4610 | F40: =TRUE() -> TRUE
...

Sheet Sales_Reps
A1: rep_id | B1: rep_name | C1: region | D1: hire_date | E1: team_lead_id
A2: R001 | B2: Rajesh Malhotra | C2: North | D2: 44207
A3: R002 | B3: Sunita Malhotra | C3: North | D3: 44028
A4: R003 | B4: Amit Singh | C4: North | D4: 43651
A5: R004 | B5: Priya Singh | C5: North | D5: 44907
A6: R005 | B6: Vikram Patel | C6: North | D6: 43588 | E6: R001
A7: R006 | B7: Neha Desai | C7: North | D7: 44131 | E7: R001
A8: R007 | B8: Suresh Menon | C8: North | D8: 43493 | E8: R001
A9: R008 | B9: Kavita Patel | C9: North | D9: 44693 | E9: R001
A10: R009 | B10: Manoj Patel | C10: South | D10: 44804 | E10: R002
A11: R010 | B11: Divya Rao | C11: South | D11: 43904 | E11: R002
A12: R011 | B12: Anil Verma | C12: South | D12: 44622 | E12: R002
A13: R012 | B13: Pooja Nair | C13: South | D13: 44890 | E13: R002
A14: R013 | B14: Sanjay Kapoor | C14: South | D14: 45215 | E14: R002
A15: R014 | B15: Ritu Menon | C15: South | D15: 44469 | E15: R002
A16: R015 | B16: Deepak Shah | C16: South | D16: 45231 | E16: R002
A17: R016 | B17: Anjali Chopra | C17: South | D17: 43614 | E17: R002
... A31: R030 | B31: Kiran Bhatt | C31: West | D31: 44506 | E31: R004

Sheet Targets
A1: rep_id | B1: Jan-24 | C1: Feb-24 | D1: Mar-24 | E1: Apr-24 | F1: May-24 | G1: Jun-24 | H1: Jul-24 | I1: Aug-24 | J1: Sep-24 | K1: Oct-24 | L1: Nov-24 | M1: Dec-24
A2: R001 | B2: 231324 | C2: 171682 | D2: 234376 | E2: 326967 | F2: 350588 | G2: 385324 | H2: 307980 | I2: 327947 | J2: 181016 | K2: 374039 | L2: 212805 | M2: 405999
A3: R002 | B3: 438126 | C3: 346266 | D3: 329993 | E3: 370744 | F3: 294660 | G3: 341556 | H3: 151934 | I3: 223794 | J3: 438641 | K3: 344308 | L3: 296172 | M3: 304288
A4: R003 | B4: 358703 | C4: 320519 | D4: 327321 | E4: 298753 | F4: 254636 | G4: 351929 | H4: 264723 | I4: 216459 | J4: 391945 | K4: 362426 | L4: 289199 | M4: 301863
A5: R004 | B5: 389594 | C5: 376422 | D5: 324156 | E5: 420255 | F5: 409107 | G5: 269954 | H5: 179097 | I5: 370568 | J5: 387395 | K5: 243454 | L5: 232530 | M5: 201999
A6: R005 | B6: 436862 | C6: 391158 | D6: 340224 | E6: 170548 | F6: 229390 | G6: 349525 | H6: 154683 | I6: 320848 | J6: 354452 | K6: 377180 | L6: 342347 | M6: 183362
A7: R006 | B7: 348734 | C7: 358191 | D7: 250385 | E7: 219657 | F7: 249365 | G7: 435704 | H7: 260892 | I7: 250741 | J7: 358402 | K7: 379858 | L7: 213280 | M7: 224634
A8: R007 | B8: 280057 | C8: 330342 | D8: 336856 | E8: 227425 | F8: 233647 | G8: 307088 | H8: 370724 | I8: 440008 | J8: 406347 | K8: 217357 | L8: 299289 | M8: 214568
A9: R008 | B9: 252886 | C9: 206057 | D9: 318209 | E9: 411230 | F9: 448660 | G9: 171135 | H9: 305339 | I9: 432264 | J9: 294273 | K9: 371409 | L9: 284207 | M9: 437068
A10: R009 | B10: 268752 | C10: 393256 | D10: 310649 | E10: 246237 | F10: 271287 | G10: 314545 | H10: 406506 | I10: 334930 | J10: 348625 | K10: 408928 | L10: 243749 | M10: 418409
A11: R010 | B11: 384734 | C11: 156698 | D11: 283679 | E11: 276085 | F11: 409270 | G11: 285230 | H11: 304233 | I11: 178221 | J11: 284216 | K11: 287373 | L11: 229082 | M11: 298969
A12: R011 | B12: 186029 | C12: 151419 | D12: 253251 | E12: 379757 | F12: 204209 | G12: 179396 | H12: 378008 | I12: 182649 | J12: 267772 | K12: 350352 | L12: 358042 | M12: 359960
A13: R012 | B13: 352158 | C13: 251181 | D13: 321255 | E13: 300863 | F13: 241731 | G13: 393275 | H13: 313561 | I13: 283604 | J13: 429065 | K13: 194420 | L13: 254168 | M13: 389283
... A31: R030 | B31: 151584 | C31: 221679 | D31: 385157 | E31: 290386 | F31: 236041 | G31: 407985 | H31: 184446 | I31: 342894 | J31: 180344 | K31: 292917 | L31: 314858 | M31: 364057

Sheet Q1_Lookups
A1: Q1 - LOOKUP FUNCTIONS (25 marks total)
A2: VLOOKUP · INDEX-MATCH · Two-way lookup · Chain lookup · Approximate lookup · Self-join
A4: Q# | B4: Question | C4: Marks | D4: Hint | E4: Your Answer | F4: Format
A5: Q1.1 | B5: For order ORD-00234, what is the customer_id? | C5: 3 | D5: Simple VLOOKUP on Orders sheet. | E5: =VLOOKUP("ORD-00234",Orders!A:C,3,FALSE()) -> CUST-0173 | F5: CUST-####
A6: Q1.2 | B6: For order ORD-00456, what is the product_name? (You will need to look up the product_id first, then find its name in Products.) | C6: 3 | D6: Two-step lookup, or nested VLOOKUP. | E6: =VLOOKUP(VLOOKUP("ORD-00456",Orders!A:D,4,FALSE()),Products!A:B,2,FALSE()) -> Dumbbells 5kg | F6: Text
A7: Q1.3 | B7: For order ORD-00987, what is the rep_name of the sales rep? Note: the rep_name is in a column that appears to the LEFT of what you might look up first. | C7: 3 | D7: VLOOKUP has directional limits - INDEX/MATCH does not. | E7: =INDEX(Sales_Reps!B:B,MATCH(VLOOKUP("ORD-00987",Orders!A:E,5,FALSE()),Sales_Reps!A:A,0)) -> #N/A | F7: Text
A8: Q1.4 | B8: From the Targets sheet, what is the target value for rep R012 in the month Mar-24? | C8: 4 | D8: Two-way lookup: row = rep_id, column = month. | E8: =INDEX(Targets!B:M,MATCH("R012",Targets!A:A,0),MATCH("Mar-24",Targets!B1:M1,0)) -> 321255 | F8: Whole number
A9: Q1.5 | B9: For order ORD-01500, what is the CATEGORY of the product ordered? (Chain: order → product_id → category) | C9: 4 | D9: Multi-hop lookup across sheets. | E9: =VLOOKUP(VLOOKUP("ORD-01500",Orders!A:D,4,FALSE()),Products!A:C,3,FALSE()) -> Electronics | F9: Text
A10: Q1.6 | B10: For order ORD-00789, which DISCOUNT SLAB does it fall in? Use the slab table below (rows 20-24). Slab breakpoints are the LOWER bound of each range. | C10: 3 | D10: Approximate-match VLOOKUP (sort ascending, TRUE / omit last arg). | E10: =VLOOKUP(VLOOKUP("ORD-00789", Orders!A:H, 8, FALSE()), B18:C21, 2, TRUE()) -> Bronze | F10: Text
A11: Q1.7 | B11: For order ORD-01234, in one cell produce the string: "<rep_name> (<sales_region>)" - e.g. "Amit Singh (South)". | C11: 3 | D11: Two lookups joined with & or CONCATENATE. | E11: =VLOOKUP(VLOOKUP("ORD-01234", Orders!A:E, 5, FALSE()), Sales_Reps!A:C, 2, FALSE()) & " (" & VLOOKUP(VLOOKUP("ORD-01234", Orders!A:E, 5, FALSE()), Sales_Reps!A:C, 3, FALSE()) & ")" -> #N/A | F11: Text
A12: Q1.8 | B12: What is the rep_name of the TEAM LEAD for rep R017? (The Sales_Reps sheet has team_lead_id - you need to self-join to find that person's name.) | C12: 2 | D12: Look up the team_lead_id, then look up THAT id's rep_name. | E12: =VLOOKUP(VLOOKUP("R017", Sales_Reps!A:E, 5, FALSE()), Sales_Reps!A:B, 2, FALSE()) -> Amit Singh | F12: Text
B15: DISCOUNT SLAB REFERENCE TABLE (use for Q1.6)
B17: Discount % (Lower) | C17: Slab
B18: 0 | C18: Bronze
B19: 5 | C19: Silver
B20: 15 | C20: Gold
B21: 25 | C21: Platinum

Sheet Q2_Cleaning
A1: Q2 - DATA CLEANING & QUALITY DIAGNOSTICS (20 marks total)
A2: Duplicates · Whitespace · Case Inconsistency · Referential Integrity · Discontinued SKUs · Anomaly Patterns
A4: Q# | B4: Question | C4: Marks | D4: Hint | E4: Your Answer | F4: Format
A5: Q2.1 | B5: How many DUPLICATE rows exist in the Orders sheet (i.e., how many order_id values appear more than once)? Count each duplicate as ONE (not the extras). | C5: 3 | D5: COUNTIF > 1, then count. Watch what you're counting - rows or IDs. | E5: =SUMPRODUCT((COUNTIF(Orders!$A$2:$A$2001,Orders!$A$2:$A$2001)>1)/COUNTIF(Orders!$A$2:$A$2001,Orders!$A$2:$A$2001)) -> 20 | F5: Whole number
A6: Q2.2 | B6: How many customers in the Customers sheet have LEADING or TRAILING whitespace in their customer_name? | C6: 3 | D6: Compare LEN vs LEN(TRIM). Or use SUMPRODUCT with a boolean. | E6: =SUMPRODUCT(--(Customers!B2:B301<>TRIM(Customers!B2:B301))) -> 15 | F6: Whole number
A7: Q2.3 | B7: The Customers sheet has some cities in inconsistent case (e.g., "mumbai", "MUMBAI", "Mumbai"). How many DISTINCT cities exist AFTER standardizing case? | C7: 3 | D7: Combine PROPER/UPPER with a de-dup count. SUMPRODUCT + 1/COUNTIF trick works. | E7: =SUMPRODUCT(1/COUNTIF(Customers!$D$2:$D$301,Customers!$D$2:$D$301)) -> 6 | F7: Whole number
A8: Q2.4 | B8: How many orders reference a customer_id that DOES NOT EXIST in the Customers sheet? (Broken foreign key) | C8: 4 | D8: Use MATCH with ISNA/ISERROR, then count. | E8: =SUMPRODUCT(--ISNA(MATCH(Orders!C2:C2001,Customers!A2:A301,0))) -> 30 | F8: Whole number
A9: Q2.5 | B9: How many orders reference a product that is currently DISCONTINUED (is_active = FALSE in the Products sheet)? | C9: 3 | D9: VLOOKUP the is_active flag, then count where FALSE. | E9: =SUMPRODUCT(COUNTIFS(Products!$A$2:$A$61,Orders!$D$2:$D$2001,Products!$F$2:$F$61,FALSE())) -> 174 | F9: Whole number
A10: Q2.6 | B10: Find the "suspicious pattern": how many orders have payment_status = "Cancelled" AND a discount_pct > 20%? (This pattern often indicates promo abuse - a real-world diagnostic query.) | C10: 4 | D10: COUNTIFS with two criteria. | E10: =COUNTIFS(Orders!J2:J2001, "Cancelled", Orders!H2:H2001, ">20") -> 58 | F10: Whole number

Sheet Q3_Aggregation
A1: Q3 - CONDITIONAL AGGREGATION (25 marks total)
A2: SUMIFS · COUNTIFS · AVERAGEIFS · Nested IF logic · Multi-sheet aggregation · Top-N logic
H3: SCRATCH - revenue by rep
A4: Q# | B4: Question | C4: Marks | D4: Hint | E4: Your Answer | F4: Format | H4: rep_id | I4: rep_name | J4: Total Revenue
A5: Q3.1 | B5: What is the TOTAL REVENUE (sum of final_amount) for orders in Q3 2024 (Jul-Sep) where ship_city is Mumbai? | C5: 4 | D5: SUMIFS with 3 conditions: date >= start, date <= end, city = Mumbai. Beware case issues. | E5: =SUMIFS(Orders!I:I,Orders!B:B,">="&DATE(2024,7,1),Orders!B:B,"<="&DATE(2024,9,30),Orders!K:K,"Mumbai") -> 1217239 | F5: Currency | H5: =Sales_Reps!A2 -> R001 | I5: =VLOOKUP(H5,Sales_Reps!$A:$B,2,FALSE()) -> Rajesh Malhotra | J5: =SUMIFS(Orders!$I$2:$I$2001,Orders!$E$2:$E$2001,H5) -> 0
A6: Q3.2 | B6: How many orders have discount_pct > 15% AND payment_status = "Completed"? | C6: 3 | D6: COUNTIFS with two conditions. | E6: =COUNTIFS(Orders!H:H,">15",Orders!J:J,"Completed") -> 723 | F6: Whole number | H6: =Sales_Reps!A3 -> R002 | I6: =VLOOKUP(H6,Sales_Reps!$A:$B,2,FALSE()) -> Sunita Malhotra | J6: =SUMIFS(Orders!$I$2:$I$2001,Orders!$E$2:$E$2001,H6) -> 0
A7: Q3.3 | B7: What is the AVERAGE final_amount for orders where the product CATEGORY is "Electronics" AND the customer SEGMENT is "Corporate"? Note: Both fields come from OTHER sheets - you'll need helper columns. | C7: 5 | D7: Helper columns in Orders: VLOOKUP category from Products, VLOOKUP segment from Customers. Then AVERAGEIFS. | E7: =AVERAGEIFS(Orders!$I$2:$I$2001,Orders!$L$2:$L$2001,"Electronics",Orders!$M$2:$M$2001,"Corporate") -> 13981.402 | F7: Currency | H7: =Sales_Reps!A4 -> R003 | I7: =VLOOKUP(H7,Sales_Reps!$A:$B,2,FALSE()) -> Amit Singh | J7: =SUMIFS(Orders!$I$2:$I$2001,Orders!$E$2:$E$2001,H7) -> 0
A8: Q3.4 | B8: What is the COMBINED REVENUE of the TOP 3 reps by total revenue? (Sum of the 3 highest rep totals.) | C8: 4 | D8: Compute per-rep totals, then use SUMPRODUCT with LARGE, or sort and sum top 3. | E8: =SUMPRODUCT(LARGE($J$5:$J$34,{1,2,3})) -> 65598.24 | F8: Currency | H8: =Sales_Reps!A5 -> R004 | I8: =VLOOKUP(H8,Sales_Reps!$A:$B,2,FALSE()) -> Priya Singh | J8: =SUMIFS(Orders!$I$2:$I$2001,Orders!$E$2:$E$2001,H8) -> 0
A9: Q3.5 | B9: For rep R015 in Nov-24: compute the actual revenue and compare to the target (from Targets sheet). Report the PERFORMANCE TIER using: <80% → "Below", 80-120% → "On Track", >120% → "Exceeds". Return only the tier text. | C9: 5 | D9: Nested IF (or IFS): compute actual/target ratio, then classify. | E9: =IF(SUMIFS(Orders!$I$2:$I$2001,Orders!$E$2:$E$2001,"R015",Orders!$B$2:$B$2001,">="&DATE(2024,11,1),Orders!$B$2:$B$2001,"<="&DATE(2024,11,30))/INDEX(Targets!$B:$M,MATCH("R015",Targets!$A:$A,0),MATCH("Nov-24",Targets!$B$1:$M$1,0))<0.8,"Below",IF(SUMIFS(Orders!$I$2:$I$2001,Orders!$E$2:$E$2001,"R015",Orders!$B$2:$B$2001,">="&DATE(2024,11,1),Orders!$B$2:$B$2001,"<="&DATE(2024,11,30))/INDEX(Targets!$B:$M,MATCH("R015",Targets!$A:$A,0),MATCH("Nov-24",Targets!$B$1:$M$1,0))>1.2,"Exceeds","On Track")) -> Below | F9: Text | H9: =Sales_Reps!A6 -> R005 | I9: =VLOOKUP(H9,Sales_Reps!$A:$B,2,FALSE()) -> Vikram Patel | J9: =SUMIFS(Orders!$I$2:$I$2001,Orders!$E$2:$E$2001,H9) -> 0
A10: Q3.6 | B10: What is the TOTAL revenue from Corporate segment customers aged between 30 and 40 (both inclusive)? | C10: 4 | D10: Helper columns for age and segment. Then SUMIFS with numeric range. | E10: =SUMIFS(Orders!$I$2:$I$2001,Orders!$M$2:$M$2001,"Corporate",Orders!$P$2:$P$2001,">=30",Orders!$P$2:$P$2001,"<=40") -> 982568.4 | F10: Currency | H10: =Sales_Reps!A7 -> R006 | I10: =VLOOKUP(H10,Sales_Reps!$A:$B,2,FALSE()) -> Neha Desai | J10: =SUMIFS(Orders!$I$2:$I$2001,Orders!$E$2:$E$2001,H10) -> 0
H11: =Sales_Reps!A8 -> R007 | I11: =VLOOKUP(H11,Sales_Reps!$A:$B,2,FALSE()) -> Suresh Menon | J11: =SUMIFS(Orders!$I$2:$I$2001,Orders!$E$2:$E$2001,H11) -> 24500.16
H12: =Sales_Reps!A9 -> R008 | I12: =VLOOKUP(H12,Sales_Reps!$A:$B,2,FALSE()) -> Kavita Patel | J12: =SUMIFS(Orders!$I$2:$I$2001,Orders!$E$2:$E$2001,H12) -> 1462.88
H13: =Sales_Reps!A10 -> R009 | I13: =VLOOKUP(H13,Sales_Reps!$A:$B,2,FALSE()) -> Manoj Patel | J13: =SUMIFS(Orders!$I$2:$I$2001,Orders!$E$2:$E$2001,H13) -> 3635.92
H14: =Sales_Reps!A11 -> R010 | I14: =VLOOKUP(H14,Sales_Reps!$A:$B,2,FALSE()) -> Divya Rao | J14: =SUMIFS(Orders!$I$2:$I$2001,Orders!$E$2:$E$2001,H14) -> 3085.38
H15: =Sales_Reps!A12 -> R011 | I15: =VLOOKUP(H15,Sales_Reps!$A:$B,2,FALSE()) -> Anil Verma | J15: =SUMIFS(Orders!$I$2:$I$2001,Orders!$E$2:$E$2001,H15) -> 2338.4
H16: =Sales_Reps!A13 -> R012 | I16: =VLOOKUP(H16,Sales_Reps!$A:$B,2,FALSE()) -> Pooja Nair | J16: =SUMIFS(Orders!$I$2:$I$2001,Orders!$E$2:$E$2001,H16) -> 1050.8
H17: =Sales_Reps!A14 -> R013 | I17: =VLOOKUP(H17,Sales_Reps!$A:$B,2,FALSE()) -> Sanjay Kapoor | J17: =SUMIFS(Orders!$I$2:$I$2001,Orders!$E$2:$E$2001,H17) -> 2712.96
H18: =Sales_Reps!A15 -> R014 | I18: =VLOOKUP(H18,Sales_Reps!$A:$B,2,FALSE()) -> Ritu Menon | J18: =SUMIFS(Orders!$I$2:$I$2001,Orders!$E$2:$E$2001,H18) -> 11165.44
H19: =Sales_Reps!A16 -> R015 | I19: =VLOOKUP(H19,Sales_Reps!$A:$B,2,FALSE()) -> Deepak Shah | J19: =SUMIFS(Orders!$I$2:$I$2001,Orders!$E$2:$E$2001,H19) -> 14131.26
H20: =Sales_Reps!A17 -> R016 | I20: =VLOOKUP(H20,Sales_Reps!$A:$B,2,FALSE()) -> Anjali Chopra | J20: =SUMIFS(Orders!$I$2:$I$2001,Orders!$E$2:$E$2001,H20) -> 2875.08
H21: =Sales_Reps!A18 -> R017 | I21: =VLOOKUP(H21,Sales_Reps!$A:$B,2,FALSE()) -> Naveen Singh | J21: =SUMIFS(Orders!$I$2:$I$2001,Orders!$E$2:$E$2001,H21) -> 14761.81
H22: =Sales_Reps!A19 -> R018 | I22: =VLOOKUP(H22,Sales_Reps!$A:$B,2,FALSE()) -> Shalini Patel | J22: =SUMIFS(Orders!$I$2:$I$2001,Orders!$E$2:$E$2001,H22) -> 18604.08
... H34: =Sales_Reps!A31 -> R030 | I34: =VLOOKUP(H34,Sales_Reps!$A:$B,2,FALSE()) -> Kiran Bhatt | J34: =SUMIFS(Orders!$I$2:$I$2001,Orders!$E$2:$E$2001,H34) -> 2989.8

Sheet Q4_Pivot
A1: Q4 - PIVOT TABLES (20 marks total)
A2: 2D Pivots · Filters · % of Row Total · Date Grouping · Calculated Fields · Cross-Sheet Data
A4: Q# | B4: Question | C4: Marks | D4: Hint | E4: Your Answer | F4: Format
A5: Q4.1 | B5: Build a pivot with sales_region as rows and product category as columns, values = SUM of final_amount. What value appears at the intersection of "South" and "Electronics"? | C5: 4 | D5: You need to add category (from Products) and region (from Sales_Reps) as columns to Orders first. Insert PivotTable from combined data. | E5: =SUMIFS(Orders!$I$2:$I$2001,Orders!$O$2:$O$2001,"South",Orders!$L$2:$L$2001,"Electronics") -> 11165.44 | F5: Currency
A6: Q4.2 | B6: Build a pivot: rows = order month (Jan-24 through Dec-24), columns = sales_rep_id, values = SUM of final_amount. What is the HIGHEST single value in the entire pivot? (One number.) | C6: 4 | D6: After building, use MAX() over the pivot data range, or scan visually. | E6: =MAX($I$15:$AL$26) -> 24500.16 | F6: Currency
A7: Q4.3 | B7: For the North sales_region only: what PERCENTAGE of total revenue comes from the Apparel category? Configure the pivot with Show Values As → % of Row Total. | C7: 4 | D7: Pivot: rows=region, cols=category, values=sum(final_amount), Show Values As = % of Row Total. | E7: =SUMIFS(Orders!$I$2:$I$2001,Orders!$O$2:$O$2001,"North",Orders!$L$2:$L$2001,"Apparel")/SUMIFS(Orders!$I$2:$I$2001,Orders!$O$2:$O$2001,"North") -> 1 | F7: Percentage
A8: Q4.4 | B8: Group order dates by QUARTER in a pivot. What is the total revenue for Q4 2024 (Oct-Dec)? | C8: 4 | D8: PivotTable → Group By → Quarter. Or SUMIFS with date range. | E8: =SUMIFS(Orders!I2:I2001,Orders!B2:B2001,">="&DATE(2024,10,1),Orders!B2:B2001,"<="&DATE(2024,12,31)) -> 6459443 | F8: Currency
A9: Q4.5 | B9: Create a CALCULATED FIELD in the pivot: profit_margin = (unit_price - unit_cost) / unit_price. What is the AVERAGE profit_margin for orders shipped to Delhi? Give as a percentage. | C9: 4 | D9: Add unit_cost via VLOOKUP as helper column. Create pivot calculated field, filter to Delhi. | E9: =SUMPRODUCT((TRIM(Orders!$K$2:$K$2001)="Delhi")*Orders!$R$2:$R$2001)/SUMPRODUCT(--(TRIM(Orders!$K$2:$K$2001)="Delhi")) -> 0.44903865 | F9: Percentage
H13: SCRATCH - month x rep pivot equivalent
I14: =Sales_Reps!A2 -> R001 | J14: =Sales_Reps!A3 -> R002 | K14: =Sales_Reps!A4 -> R003 | L14: =Sales_Reps!A5 -> R004 | M14: =Sales_Reps!A6 -> R005 | N14: =Sales_Reps!A7 -> R006 | O14: =Sales_Reps!A8 -> R007 | P14: =Sales_Reps!A9 -> R008 | Q14: =Sales_Reps!A10 -> R009 | R14: =Sales_Reps!A11 -> R010 | S14: =Sales_Reps!A12 -> R011 | T14: =Sales_Reps!A13 -> R012 | U14: =Sales_Reps!A14 -> R013 | V14: =Sales_Reps!A15 -> R014 | W14: =Sales_Reps!A16 -> R015 | X14: =Sales_Reps!A17 -> R016 | Y14: =Sales_Reps!A18 -> R017 | Z14: =Sales_Reps!A19 -> R018 | AA14: =Sales_Reps!A20 -> R019 | AB14: =Sales_Reps!A21 -> R020 | AC14: =Sales_Reps!A22 -> R021 | AD14: =Sales_Reps!A23 -> R022 | AE14: =Sales_Reps!A24 -> R023 | AF14: =Sales_Reps!A25 -> R024 | AG14: =Sales_Reps!A26 -> R025 | AH14: =Sales_Reps!A27 -> R026 | AI14: =Sales_Reps!A28 -> R027 | AJ14: =Sales_Reps!A29 -> R028 | AK14: =Sales_Reps!A30 -> R029 | AL14: =Sales_Reps!A31 -> R030
H15: Jan-24 | I15: =SUMIFS(Orders!$I$2:$I$2001,Orders!$Q$2:$Q$2001,$H15,Orders!$E$2:$E$2001,I$14) -> 0 | J15: =SUMIFS(Orders!$I$2:$I$2001,Orders!$Q$2:$Q$2001,$H15,Orders!$E$2:$E$2001,J$14) -> 0 | K15: =SUMIFS(Orders!$I$2:$I$2001,Orders!$Q$2:$Q$2001,$H15,Orders!$E$2:$E$2001,K$14) -> 0 | L15: =SUMIFS(Orders!$I$2:$I$2001,Orders!$Q$2:$Q$2001,$H15,Orders!$E$2:$E$2001,L$14) -> 0 | M15: =SUMIFS(Orders!$I$2:$I$2001,Orders!$Q$2:$Q$2001,$H15,Orders!$E$2:$E$2001,M$14) -> 0 | N15: =SUMIFS(Orders!$I$2:$I$2001,Orders!$Q$2:$Q$2001,$H15,Orders!$E$2:$E$2001,N$14) -> 0 | O15: =SUMIFS(Orders!$I$2:$I$2001,Orders!$Q$2:$Q$2001,$H15,Orders!$E$2:$E$2001,O$14) -> 0 | P15: =SUMIFS(Orders!$I$2:$I$2001,Orders!$Q$2:$Q$2001,$H15,Orders!$E$2:$E$2001,P$14) -> 0 | ... AL15: =SUMIFS(Orders!$I$2:$I$2001,Orders!$Q$2:$Q$2001,$H15,Orders!$E$2:$E$2001,AL$14) -> 0
H16: Feb-24 | I16: =SUMIFS(Orders!$I$2:$I$2001,Orders!$Q$2:$Q$2001,$H16,Orders!$E$2:$E$2001,I$14) -> 0 | J16: =SUMIFS(Orders!$I$2:$I$2001,Orders!$Q$2:$Q$2001,$H16,Orders!$E$2:$E$2001,J$14) -> 0 | K16: =SUMIFS(Orders!$I$2:$I$2001,Orders!$Q$2:$Q$2001,$H16,Orders!$E$2:$E$2001,K$14) -> 0 | L16: =SUMIFS(Orders!$I$2:$I$2001,Orders!$Q$2:$Q$2001,$H16,Orders!$E$2:$E$2001,L$14) -> 0 | M16: =SUMIFS(Orders!$I$2:$I$2001,Orders!$Q$2:$Q$2001,$H16,Orders!$E$2:$E$2001,M$14) -> 0 | N16: =SUMIFS(Orders!$I$2:$I$2001,Orders!$Q$2:$Q$2001,$H16,Orders!$E$2:$E$2001,N$14) -> 0 | O16: =SUMIFS(Orders!$I$2:$I$2001,Orders!$Q$2:$Q$2001,$H16,Orders!$E$2:$E$2001,O$14) -> 0 | P16: =SUMIFS(Orders!$I$2:$I$2001,Orders!$Q$2:$Q$2001,$H16,Orders!$E$2:$E$2001,P$14) -> 1462.88 | ... AL16: =SUMIFS(Orders!$I$2:$I$2001,Orders!$Q$2:$Q$2001,$H16,Orders!$E$2:$E$2001,AL$14) -> 0
H17: Mar-24 | I17: =SUMIFS(Orders!$I$2:$I$2001,Orders!$Q$2:$Q$2001,$H17,Orders!$E$2:$E$2001,I$14) -> 0 | J17: =SUMIFS(Orders!$I$2:$I$2001,Orders!$Q$2:$Q$2001,$H17,Orders!$E$2:$E$2001,J$14) -> 0 | K17: =SUMIFS(Orders!$I$2:$I$2001,Orders!$Q$2:$Q$2001,$H17,Orders!$E$2:$E$2001,K$14) -> 0 | L17: =SUMIFS(Orders!$I$2:$I$2001,Orders!$Q$2:$Q$2001,$H17,Orders!$E$2:$E$2001,L$14) -> 0 | M17: =SUMIFS(Orders!$I$2:$I$2001,Orders!$Q$2:$Q$2001,$H17,Orders!$E$2:$E$2001,M$14) -> 0 | N17: =SUMIFS(Orders!$I$2:$I$2001,Orders!$Q$2:$Q$2001,$H17,Orders!$E$2:$E$2001,N$14) -> 0 | O17: =SUMIFS(Orders!$I$2:$I$2001,Orders!$Q$2:$Q$2001,$H17,Orders!$E$2:$E$2001,O$14) -> 0 | P17: =SUMIFS(Orders!$I$2:$I$2001,Orders!$Q$2:$Q$2001,$H17,Orders!$E$2:$E$2001,P$14) -> 0 | ... AL17: =SUMIFS(Orders!$I$2:$I$2001,Orders!$Q$2:$Q$2001,$H17,Orders!$E$2:$E$2001,AL$14) -> 0
H18: Apr-24 | I18: =SUMIFS(Orders!$I$2:$I$2001,Orders!$Q$2:$Q$2001,$H18,Orders!$E$2:$E$2001,I$14) -> 0 | J18: =SUMIFS(Orders!$I$2:$I$2001,Orders!$Q$2:$Q$2001,$H18,Orders!$E$2:$E$2001,J$14) -> 0 | K18: =SUMIFS(Orders!$I$2:$I$2001,Orders!$Q$2:$Q$2001,$H18,Orders!$E$2:$E$2001,K$14) -> 0 | L18: =SUMIFS(Orders!$I$2:$I$2001,Orders!$Q$2:$Q$2001,$H18,Orders!$E$2:$E$2001,L$14) -> 0 | M18: =SUMIFS(Orders!$I$2:$I$2001,Orders!$Q$2:$Q$2001,$H18,Orders!$E$2:$E$2001,M$14) -> 0 | N18: =SUMIFS(Orders!$I$2:$I$2001,Orders!$Q$2:$Q$2001,$H18,Orders!$E$2:$E$2001,N$14) -> 0 | O18: =SUMIFS(Orders!$I$2:$I$2001,Orders!$Q$2:$Q$2001,$H18,Orders!$E$2:$E$2001,O$14) -> 0 | P18: =SUMIFS(Orders!$I$2:$I$2001,Orders!$Q$2:$Q$2001,$H18,Orders!$E$2:$E$2001,P$14) -> 0 | ... AL18: =SUMIFS(Orders!$I$2:$I$2001,Orders!$Q$2:$Q$2001,$H18,Orders!$E$2:$E$2001,AL$14) -> 0
H19: May-24 | I19: =SUMIFS(Orders!$I$2:$I$2001,Orders!$Q$2:$Q$2001,$H19,Orders!$E$2:$E$2001,I$14) -> 0 | J19: =SUMIFS(Orders!$I$2:$I$2001,Orders!$Q$2:$Q$2001,$H19,Orders!$E$2:$E$2001,J$14) -> 0 | K19: =SUMIFS(Orders!$I$2:$I$2001,Orders!$Q$2:$Q$2001,$H19,Orders!$E$2:$E$2001,K$14) -> 0 | L19: =SUMIFS(Orders!$I$2:$I$2001,Orders!$Q$2:$Q$2001,$H19,Orders!$E$2:$E$2001,L$14) -> 0 | M19: =SUMIFS(Orders!$I$2:$I$2001,Orders!$Q$2:$Q$2001,$H19,Orders!$E$2:$E$2001,M$14) -> 0 | N19: =SUMIFS(Orders!$I$2:$I$2001,Orders!$Q$2:$Q$2001,$H19,Orders!$E$2:$E$2001,N$14) -> 0 | O19: =SUMIFS(Orders!$I$2:$I$2001,Orders!$Q$2:$Q$2001,$H19,Orders!$E$2:$E$2001,O$14) -> 0 | P19: =SUMIFS(Orders!$I$2:$I$2001,Orders!$Q$2:$Q$2001,$H19,Orders!$E$2:$E$2001,P$14) -> 0 | ... AL19: =SUMIFS(Orders!$I$2:$I$2001,Orders!$Q$2:$Q$2001,$H19,Orders!$E$2:$E$2001,AL$14) -> 0
H20: Jun-24 | I20: =SUMIFS(Orders!$I$2:$I$2001,Orders!$Q$2:$Q$2001,$H20,Orders!$E$2:$E$2001,I$14) -> 0 | J20: =SUMIFS(Orders!$I$2:$I$2001,Orders!$Q$2:$Q$2001,$H20,Orders!$E$2:$E$2001,J$14) -> 0 | K20: =SUMIFS(Orders!$I$2:$I$2001,Orders!$Q$2:$Q$2001,$H20,Orders!$E$2:$E$2001,K$14) -> 0 | L20: =SUMIFS(Orders!$I$2:$I$2001,Orders!$Q$2:$Q$2001,$H20,Orders!$E$2:$E$2001,L$14) -> 0 | M20: =SUMIFS(Orders!$I$2:$I$2001,Orders!$Q$2:$Q$2001,$H20,Orders!$E$2:$E$2001,M$14) -> 0 | N20: =SUMIFS(Orders!$I$2:$I$2001,Orders!$Q$2:$Q$2001,$H20,Orders!$E$2:$E$2001,N$14) -> 0 | O20: =SUMIFS(Orders!$I$2:$I$2001,Orders!$Q$2:$Q$2001,$H20,Orders!$E$2:$E$2001,O$14) -> 0 | P20: =SUMIFS(Orders!$I$2:$I$2001,Orders!$Q$2:$Q$2001,$H20,Orders!$E$2:$E$2001,P$14) -> 0 | ... AL20: =SUMIFS(Orders!$I$2:$I$2001,Orders!$Q$2:$Q$2001,$H20,Orders!$E$2:$E$2001,AL$14) -> 2989.8
H21: Jul-24 | I21: =SUMIFS(Orders!$I$2:$I$2001,Orders!$Q$2:$Q$2001,$H21,Orders!$E$2:$E$2001,I$14) -> 0 | J21: =SUMIFS(Orders!$I$2:$I$2001,Orders!$Q$2:$Q$2001,$H21,Orders!$E$2:$E$2001,J$14) -> 0 | K21: =SUMIFS(Orders!$I$2:$I$2001,Orders!$Q$2:$Q$2001,$H21,Orders!$E$2:$E$2001,K$14) -> 0 | L21: =SUMIFS(Orders!$I$2:$I$2001,Orders!$Q$2:$Q$2001,$H21,Orders!$E$2:$E$2001,L$14) -> 0 | M21: =SUMIFS(Orders!$I$2:$I$2001,Orders!$Q$2:$Q$2001,$H21,Orders!$E$2:$E$2001,M$14) -> 0 | N21: =SUMIFS(Orders!$I$2:$I$2001,Orders!$Q$2:$Q$2001,$H21,Orders!$E$2:$E$2001,N$14) -> 0 | O21: =SUMIFS(Orders!$I$2:$I$2001,Orders!$Q$2:$Q$2001,$H21,Orders!$E$2:$E$2001,O$14) -> 0 | P21: =SUMIFS(Orders!$I$2:$I$2001,Orders!$Q$2:$Q$2001,$H21,Orders!$E$2:$E$2001,P$14) -> 0 | ... AL21: =SUMIFS(Orders!$I$2:$I$2001,Orders!$Q$2:$Q$2001,$H21,Orders!$E$2:$E$2001,AL$14) -> 0
H22: Aug-24 | I22: =SUMIFS(Orders!$I$2:$I$2001,Orders!$Q$2:$Q$2001,$H22,Orders!$E$2:$E$2001,I$14) -> 0 | J22: =SUMIFS(Orders!$I$2:$I$2001,Orders!$Q$2:$Q$2001,$H22,Orders!$E$2:$E$2001,J$14) -> 0 | K22: =SUMIFS(Orders!$I$2:$I$2001,Orders!$Q$2:$Q$2001,$H22,Orders!$E$2:$E$2001,K$14) -> 0 | L22: =SUMIFS(Orders!$I$2:$I$2001,Orders!$Q$2:$Q$2001,$H22,Orders!$E$2:$E$2001,L$14) -> 0 | M22: =SUMIFS(Orders!$I$2:$I$2001,Orders!$Q$2:$Q$2001,$H22,Orders!$E$2:$E$2001,M$14) -> 0 | N22: =SUMIFS(Orders!$I$2:$I$2001,Orders!$Q$2:$Q$2001,$H22,Orders!$E$2:$E$2001,N$14) -> 0 | O22: =SUMIFS(Orders!$I$2:$I$2001,Orders!$Q$2:$Q$2001,$H22,Orders!$E$2:$E$2001,O$14) -> 0 | P22: =SUMIFS(Orders!$I$2:$I$2001,Orders!$Q$2:$Q$2001,$H22,Orders!$E$2:$E$2001,P$14) -> 0 | ... AL22: =SUMIFS(Orders!$I$2:$I$2001,Orders!$Q$2:$Q$2001,$H22,Orders!$E$2:$E$2001,AL$14) -> 0
H23: Sep-24 | I23: =SUMIFS(Orders!$I$2:$I$2001,Orders!$Q$2:$Q$2001,$H23,Orders!$E$2:$E$2001,I$14) -> 0 | J23: =SUMIFS(Orders!$I$2:$I$2001,Orders!$Q$2:$Q$2001,$H23,Orders!$E$2:$E$2001,J$14) -> 0 | K23: =SUMIFS(Orders!$I$2:$I$2001,Orders!$Q$2:$Q$2001,$H23,Orders!$E$2:$E$2001,K$14) -> 0 | L23: =SUMIFS(Orders!$I$2:$I$2001,Orders!$Q$2:$Q$2001,$H23,Orders!$E$2:$E$2001,L$14) -> 0 | M23: =SUMIFS(Orders!$I$2:$I$2001,Orders!$Q$2:$Q$2001,$H23,Orders!$E$2:$E$2001,M$14) -> 0 | N23: =SUMIFS(Orders!$I$2:$I$2001,Orders!$Q$2:$Q$2001,$H23,Orders!$E$2:$E$2001,N$14) -> 0 | O23: =SUMIFS(Orders!$I$2:$I$2001,Orders!$Q$2:$Q$2001,$H23,Orders!$E$2:$E$2001,O$14) -> 24500.16 | P23: =SUMIFS(Orders!$I$2:$I$2001,Orders!$Q$2:$Q$2001,$H23,Orders!$E$2:$E$2001,P$14) -> 0 | ... AL23: =SUMIFS(Orders!$I$2:$I$2001,Orders!$Q$2:$Q$2001,$H23,Orders!$E$2:$E$2001,AL$14) -> 0
H24: Oct-24 | I24: =SUMIFS(Orders!$I$2:$I$2001,Orders!$Q$2:$Q$2001,$H24,Orders!$E$2:$E$2001,I$14) -> 0 | J24: =SUMIFS(Orders!$I$2:$I$2001,Orders!$Q$2:$Q$2001,$H24,Orders!$E$2:$E$2001,J$14) -> 0 | K24: =SUMIFS(Orders!$I$2:$I$2001,Orders!$Q$2:$Q$2001,$H24,Orders!$E$2:$E$2001,K$14) -> 0 | L24: =SUMIFS(Orders!$I$2:$I$2001,Orders!$Q$2:$Q$2001,$H24,Orders!$E$2:$E$2001,L$14) -> 0 | M24: =SUMIFS(Orders!$I$2:$I$2001,Orders!$Q$2:$Q$2001,$H24,Orders!$E$2:$E$2001,M$14) -> 0 | N24: =SUMIFS(Orders!$I$2:$I$2001,Orders!$Q$2:$Q$2001,$H24,Orders!$E$2:$E$2001,N$14) -> 0 | O24: =SUMIFS(Orders!$I$2:$I$2001,Orders!$Q$2:$Q$2001,$H24,Orders!$E$2:$E$2001,O$14) -> 0 | P24: =SUMIFS(Orders!$I$2:$I$2001,Orders!$Q$2:$Q$2001,$H24,Orders!$E$2:$E$2001,P$14) -> 0 | ... AL24: =SUMIFS(Orders!$I$2:$I$2001,Orders!$Q$2:$Q$2001,$H24,Orders!$E$2:$E$2001,AL$14) -> 0
H25: Nov-24 | I25: =SUMIFS(Orders!$I$2:$I$2001,Orders!$Q$2:$Q$2001,$H25,Orders!$E$2:$E$2001,I$14) -> 0 | J25: =SUMIFS(Orders!$I$2:$I$2001,Orders!$Q$2:$Q$2001,$H25,Orders!$E$2:$E$2001,J$14) -> 0 | K25: =SUMIFS(Orders!$I$2:$I$2001,Orders!$Q$2:$Q$2001,$H25,Orders!$E$2:$E$2001,K$14) -> 0 | L25: =SUMIFS(Orders!$I$2:$I$2001,Orders!$Q$2:$Q$2001,$H25,Orders!$E$2:$E$2001,L$14) -> 0 | M25: =SUMIFS(Orders!$I$2:$I$2001,Orders!$Q$2:$Q$2001,$H25,Orders!$E$2:$E$2001,M$14) -> 0 | N25: =SUMIFS(Orders!$I$2:$I$2001,Orders!$Q$2:$Q$2001,$H25,Orders!$E$2:$E$2001,N$14) -> 0 | O25: =SUMIFS(Orders!$I$2:$I$2001,Orders!$Q$2:$Q$2001,$H25,Orders!$E$2:$E$2001,O$14) -> 0 | P25: =SUMIFS(Orders!$I$2:$I$2001,Orders!$Q$2:$Q$2001,$H25,Orders!$E$2:$E$2001,P$14) -> 0 | ... AL25: =SUMIFS(Orders!$I$2:$I$2001,Orders!$Q$2:$Q$2001,$H25,Orders!$E$2:$E$2001,AL$14) -> 0
H26: Dec-24 | I26: =SUMIFS(Orders!$I$2:$I$2001,Orders!$Q$2:$Q$2001,$H26,Orders!$E$2:$E$2001,I$14) -> 0 | J26: =SUMIFS(Orders!$I$2:$I$2001,Orders!$Q$2:$Q$2001,$H26,Orders!$E$2:$E$2001,J$14) -> 0 | K26: =SUMIFS(Orders!$I$2:$I$2001,Orders!$Q$2:$Q$2001,$H26,Orders!$E$2:$E$2001,K$14) -> 0 | L26: =SUMIFS(Orders!$I$2:$I$2001,Orders!$Q$2:$Q$2001,$H26,Orders!$E$2:$E$2001,L$14) -> 0 | M26: =SUMIFS(Orders!$I$2:$I$2001,Orders!$Q$2:$Q$2001,$H26,Orders!$E$2:$E$2001,M$14) -> 0 | N26: =SUMIFS(Orders!$I$2:$I$2001,Orders!$Q$2:$Q$2001,$H26,Orders!$E$2:$E$2001,N$14) -> 0 | O26: =SUMIFS(Orders!$I$2:$I$2001,Orders!$Q$2:$Q$2001,$H26,Orders!$E$2:$E$2001,O$14) -> 0 | P26: =SUMIFS(Orders!$I$2:$I$2001,Orders!$Q$2:$Q$2001,$H26,Orders!$E$2:$E$2001,P$14) -> 0 | ... AL26: =SUMIFS(Orders!$I$2:$I$2001,Orders!$Q$2:$Q$2001,$H26,Orders!$E$2:$E$2001,AL$14) -> 0

Sheet Q5_Advanced
A1: Q5 - ADVANCED (10 marks total)
A2: RANK · Running Totals · TEXTJOIN · LARGE + INDEX/MATCH · Multi-condition top-N
H3: SCRATCH - West-region revenue by product
A4: Q# | B4: Question | C4: Marks | D4: Hint | E4: Your Answer | F4: Format | H4: product_id | I4: product_name | J4: West Revenue
A5: Q5.1 | B5: Rank all sales reps by total revenue (highest = rank 1). Who (name) is at RANK #7? | C5: 2 | D5: Per-rep totals, then use RANK.EQ, or sort. Return the rep_name at position 7. | E5: =INDEX(Q3_Aggregation!$I$5:$I$34,MATCH(LARGE(Q3_Aggregation!$J$5:$J$34,7),Q3_Aggregation!$J$5:$J$34,0)) -> Naveen Singh | F5: Text | H5: =Products!A2 -> PROD-001 | I5: =VLOOKUP(H5,Products!$A:$B,2,FALSE()) -> Smartphone Pro | J5: =SUMIFS(Orders!$I$2:$I$2001,Orders!$O$2:$O$2001,"West",Orders!$D$2:$D$2001,H5) -> 0
A6: Q5.2 | B6: What is the CUMULATIVE revenue from Jan 2024 through the end of Aug 2024? (Sum of final_amount where order_date <= 31-Aug-2024.) | C6: 2 | D6: SUMIFS with date <=. | E6: =SUMIFS(Orders!$I$2:$I$2001,Orders!$B$2:$B$2001,"<="&DATE(2024,8,31)) -> 18050690 | F6: Currency | H6: =Products!A3 -> PROD-002 | I6: =VLOOKUP(H6,Products!$A:$B,2,FALSE()) -> Wireless Earbuds | J6: =SUMIFS(Orders!$I$2:$I$2001,Orders!$O$2:$O$2001,"West",Orders!$D$2:$D$2001,H6) -> 0
A7: Q5.3 | B7: Among orders where the sales rep is in the WEST region: which product (by name) has the 2nd highest total revenue? | C7: 3 | D7: Helper: sales_region on orders. Filter/pivot to West, sum by product, rank, get #2, VLOOKUP product name. | E7: =INDEX($I$5:$I$64,MATCH(LARGE($J$5:$J$64,2),$J$5:$J$64,0)) -> Sports Shoes | F7: Text | H7: =Products!A4 -> PROD-003 | I7: =VLOOKUP(H7,Products!$A:$B,2,FALSE()) -> Smart Watch | J7: =SUMIFS(Orders!$I$2:$I$2001,Orders!$O$2:$O$2001,"West",Orders!$D$2:$D$2001,H7) -> 0
A8: Q5.4 | B8: Concatenate the names of the top 5 reps by revenue into a single cell, separated by " | " (space-pipe-space). | C8: 2 | D8: TEXTJOIN with delimiter " | ". Combine with LARGE to pull top 5. | E8: =_xlfn.TEXTJOIN(" | ",TRUE(),INDEX(Q3_Aggregation!$I$5:$I$34,MATCH(LARGE(Q3_Aggregation!$J$5:$J$34,1),Q3_Aggregation!$J$5:$J$34,0)),INDEX(Q3_Aggregation!$I$5:$I$34,MATCH(LARGE(Q3_Aggregation!$J$5:$J$34,2),Q3_Aggregation!$J$5:$J$34,0)),INDEX(Q3_Aggregation!$I$5:$I$34,MATCH(LARGE(Q3_Aggregation!$J$5:$J$34,3),Q3_Aggregation!$J$5:$J$34,0)),INDEX(Q3_Aggregation!$I$5:$I$34,MATCH(LARGE(Q3_Aggregation!$J$5:$J$34,4),Q3_Aggregation!$J$5:$J$34,0)),INDEX(Q3_Aggregation!$I$5:$I$34,MATCH(LARGE(Q3_Aggregation!$J$5:$J$34,5),Q3_Aggregation!$J$5:$J$34,0))) -> Suresh Menon | Rekha Chopra | Shalini Patel | Arun Iyer | Ashok Reddy | F8: Text | H8: =Products!A5 -> PROD-004 | I8: =VLOOKUP(H8,Products!$A:$B,2,FALSE()) -> Laptop Bag | J8: =SUMIFS(Orders!$I$2:$I$2001,Orders!$O$2:$O$2001,"West",Orders!$D$2:$D$2001,H8) -> 0
A9: Q5.5 | B9: What is the HIGHEST single order value (final_amount) where ship_city = "Bengaluru" AND the product's category = "Grocery"? | C9: 1 | D9: MAXIFS with a category helper column, or nested MAX(IF()). | E9: =SUMPRODUCT(MAX((TRIM(Orders!$K$2:$K$2001)="Bengaluru")*(Orders!$L$2:$L$2001="Grocery")*Orders!$I$2:$I$2001)) -> 39666.2 | F9: Currency | H9: =Products!A6 -> PROD-005 | I9: =VLOOKUP(H9,Products!$A:$B,2,FALSE()) -> Power Bank | J9: =SUMIFS(Orders!$I$2:$I$2001,Orders!$O$2:$O$2001,"West",Orders!$D$2:$D$2001,H9) -> 0
H10: =Products!A7 -> PROD-006 | I10: =VLOOKUP(H10,Products!$A:$B,2,FALSE()) -> Bluetooth Speaker | J10: =SUMIFS(Orders!$I$2:$I$2001,Orders!$O$2:$O$2001,"West",Orders!$D$2:$D$2001,H10) -> 0
H11: =Products!A8 -> PROD-007 | I11: =VLOOKUP(H11,Products!$A:$B,2,FALSE()) -> USB-C Cable | J11: =SUMIFS(Orders!$I$2:$I$2001,Orders!$O$2:$O$2001,"West",Orders!$D$2:$D$2001,H11) -> 0
H12: =Products!A9 -> PROD-008 | I12: =VLOOKUP(H12,Products!$A:$B,2,FALSE()) -> Wireless Mouse | J12: =SUMIFS(Orders!$I$2:$I$2001,Orders!$O$2:$O$2001,"West",Orders!$D$2:$D$2001,H12) -> 0
H13: =Products!A10 -> PROD-009 | I13: =VLOOKUP(H13,Products!$A:$B,2,FALSE()) -> Mechanical Keyboard | J13: =SUMIFS(Orders!$I$2:$I$2001,Orders!$O$2:$O$2001,"West",Orders!$D$2:$D$2001,H13) -> 0
H14: =Products!A11 -> PROD-010 | I14: =VLOOKUP(H14,Products!$A:$B,2,FALSE()) -> Tablet Stand | J14: =SUMIFS(Orders!$I$2:$I$2001,Orders!$O$2:$O$2001,"West",Orders!$D$2:$D$2001,H14) -> 0
H15: =Products!A12 -> PROD-011 | I15: =VLOOKUP(H15,Products!$A:$B,2,FALSE()) -> Cotton T-Shirt | J15: =SUMIFS(Orders!$I$2:$I$2001,Orders!$O$2:$O$2001,"West",Orders!$D$2:$D$2001,H15) -> 0
H16: =Products!A13 -> PROD-012 | I16: =VLOOKUP(H16,Products!$A:$B,2,FALSE()) -> Denim Jeans | J16: =SUMIFS(Orders!$I$2:$I$2001,Orders!$O$2:$O$2001,"West",Orders!$D$2:$D$2001,H16) -> 0
H17: =Products!A14 -> PROD-013 | I17: =VLOOKUP(H17,Products!$A:$B,2,FALSE()) -> Formal Shirt | J17: =SUMIFS(Orders!$I$2:$I$2001,Orders!$O$2:$O$2001,"West",Orders!$D$2:$D$2001,H17) -> 0
H18: =Products!A15 -> PROD-014 | I18: =VLOOKUP(H18,Products!$A:$B,2,FALSE()) -> Winter Jacket | J18: =SUMIFS(Orders!$I$2:$I$2001,Orders!$O$2:$O$2001,"West",Orders!$D$2:$D$2001,H18) -> 0
H19: =Products!A16 -> PROD-015 | I19: =VLOOKUP(H19,Products!$A:$B,2,FALSE()) -> Sports Shoes | J19: =SUMIFS(Orders!$I$2:$I$2001,Orders!$O$2:$O$2001,"West",Orders!$D$2:$D$2001,H19) -> 18066.24
H20: =Products!A17 -> PROD-016 | I20: =VLOOKUP(H20,Products!$A:$B,2,FALSE()) -> Casual Sneakers | J20: =SUMIFS(Orders!$I$2:$I$2001,Orders!$O$2:$O$2001,"West",Orders!$D$2:$D$2001,H20) -> 0
H21: =Products!A18 -> PROD-017 | I21: =VLOOKUP(H21,Products!$A:$B,2,FALSE()) -> Silk Saree | J21: =SUMIFS(Orders!$I$2:$I$2001,Orders!$O$2:$O$2001,"West",Orders!$D$2:$D$2001,H21) -> 0
... H64: =Products!A61 -> PROD-060 | I64: =VLOOKUP(H64,Products!$A:$B,2,FALSE()) -> Gym Gloves | J64: =SUMIFS(Orders!$I$2:$I$2001,Orders!$O$2:$O$2001,"West",Orders!$D$2:$D$2001,H64) -> 0
